<?xml version='1.0' encoding='utf-8'?>
<robot name="gregor" xmlns:gz="http://gazebosim.org/schema">
    <link name="base_footprint"/>
    <!-- +π/2 yaw aligns Fusion's base_link axes with REP-103 so the
         MecanumDrive plugin's IK matches physics. See wiki: Hardware-Robot-Model. -->
    <joint name="base_footprint_to_base_link" type="fixed">
        <parent link="base_footprint"/>
        <child link="base_link"/>
        <origin xyz="0 0 0.025" rpy="0 0 1.5708"/>
    </joint>

    <link name="upper_level_link">
        <inertial>
            <origin xyz="0.002397 -0.001362 0.037792" rpy="0 0 0" />
            <mass value="0.136512" />
            <inertia ixx="0.000343" iyy="0.00018" izz="0.000299" ixy="-7.90917e-07" iyz="2.10696e-05" ixz="-3.2061e-06" />
        </inertial>
        <visual name="Upper-Level_visual">
            <origin xyz="-0.008 0 -0.008" rpy="0 0 1.5708" />
            <geometry>
                <mesh filename="package://gregor_description/meshes/Upper-Level.stl" scale="0.001 0.001 0.001" />
            </geometry>
            <material name="frame_grey"><color rgba="0.28 0.28 0.28 1.0"/></material>
        </visual>
    </link>
    <link name="battery_link">
        <inertial>
            <origin xyz="0 0 0.017924" rpy="0 0 0" />
            <mass value="0.096971" />
            <inertia ixx="4.90915e-05" iyy="2.04656e-05" izz="4.87766e-05" ixy="0" iyz="0" ixz="0" />
        </inertial>
        <visual name="Battery_visual">
            <origin xyz="-0.00875 0.00025 0" rpy="3.14159 0 -1.5708" />
            <geometry>
                <mesh filename="package://gregor_description/meshes/Battery.stl" scale="0.001 0.001 0.001" />
            </geometry>
            <material name="battery_slate"><color rgba="0.13 0.16 0.22 1.0"/></material>
        </visual>
    </link>
    <link name="camera_link">
        <inertial>
            <origin xyz="0.003779 -0.016 -0.016" rpy="0 0 0" />
            <mass value="0.007058" />
            <inertia ixx="7.38569e-07" iyy="4.60969e-07" izz="4.60969e-07" ixy="0" iyz="0" ixz="0" />
        </inertial>
        <visual name="RGB-Camera_visual">
            <origin xyz="0.0025 -0.002 -0.05" rpy="1.5708 0 1.5708" />
            <geometry>
                <mesh filename="package://gregor_description/meshes/RGB-Camera.stl" scale="0.001 0.001 0.001" />
            </geometry>
            <material name="camera_black"><color rgba="0.08 0.08 0.08 1.0"/></material>
        </visual>
    </link>
    <link name="range_front_link">
        <inertial>
            <origin xyz="-0.01075 -0.01275 -0.0055" rpy="0 0 0" />
            <mass value="0.011157" />
            <inertia ixx="7.17062e-07" iyy="5.42271e-07" izz="1.03434e-06" ixy="0" iyz="0" ixz="0" />
        </inertial>
        <visual name="Avstands-sensor-fremme_visual">
            <origin xyz="-0.140622 -0.0129 0.005" rpy="0 0 1.5708" />
            <geometry>
                <mesh filename="package://gregor_description/meshes/Avstands-sensor-fremme.stl" scale="0.001 0.001 0.001" />
            </geometry>
            <material name="sensor_white"><color rgba="0.92 0.92 0.92 1.0"/></material>
        </visual>
    </link>
    <link name="base_link">
        <inertial>
            <origin xyz="0.00057 -0.001005 0.003313" rpy="0 0 0" />
            <mass value="0.292165" />
            <inertia ixx="0.001293" iyy="0.000259" izz="0.001519" ixy="-8.67302e-06" iyz="-1.71336e-05" ixz="-1.95881e-06" />
        </inertial>
        <visual name="Chassie_visual">
            <origin xyz="0 0 0" rpy="0 0 0" />
            <geometry>
                <mesh filename="package://gregor_description/meshes/Chassie.stl" scale="0.001 0.001 0.001" />
            </geometry>
            <material name="chassis_grey"><color rgba="0.22 0.22 0.22 1.0"/></material>
        </visual>
    </link>
    <link name="range_rear_link">
        <inertial>
            <origin xyz="0.01075 -0.01275 0.0055" rpy="0 0 0" />
            <mass value="0.011157" />
            <inertia ixx="7.17062e-07" iyy="5.42271e-07" izz="1.03434e-06" ixy="0" iyz="0" ixz="0" />
        </inertial>
        <visual name="Avstands-sensor-bak_visual">
            <origin xyz="0.1255 -0.01273 -0.008" rpy="3.14159 0 -1.5708" />
            <geometry>
                <mesh filename="package://gregor_description/meshes/Avstands-sensor-bak.stl" scale="0.001 0.001 0.001" />
            </geometry>
            <material name="sensor_black"><color rgba="0.08 0.08 0.08 1.0"/></material>
        </visual>
    </link>
    <link name="thermal_camera_link">
        <inertial>
            <origin xyz="0.001776 -0.012621 0.010365" rpy="0 0 0" />
            <mass value="0.003087" />
            <inertia ixx="3.05671e-07" iyy="1.35055e-07" izz="1.89396e-07" ixy="-1.28368e-08" iyz="0" ixz="0" />
        </inertial>
        <visual name="Thermal-camera_visual">
            <origin xyz="0.002 -0.026351 0.020716" rpy="0 1.5708 0" />
            <geometry>
                <mesh filename="package://gregor_description/meshes/Thermal-camera.stl" scale="0.001 0.001 0.001" />
            </geometry>
            <material name="sensor_black"><color rgba="0.08 0.08 0.08 1.0"/></material>
        </visual>
    </link>
    <link name="range_left_link">
        <inertial>
            <origin xyz="0.01275 -0.01075 -0.0055" rpy="0 0 0" />
            <mass value="0.011157" />
            <inertia ixx="5.42271e-07" iyy="7.17062e-07" izz="1.03434e-06" ixy="0" iyz="0" ixz="0" />
        </inertial>
        <visual name="Avstands-sensor-venstre_visual">
            <origin xyz="-0.013462 0.019105 -0.0002" rpy="0 0 -3.14159" />
            <geometry>
                <mesh filename="package://gregor_description/meshes/Avstands-sensor-venstre.stl" scale="0.001 0.001 0.001" />
            </geometry>
            <material name="sensor_white"><color rgba="0.92 0.92 0.92 1.0"/></material>
        </visual>
    </link>
    <link name="motor_fr_link">
        <inertial>
            <origin xyz="0 0.024943 0" rpy="0 0 0" />
            <mass value="0.154411" />
            <inertia ixx="2.67125e-05" iyy="1.20421e-05" izz="2.67125e-05" ixy="0" iyz="0" ixz="0" />
        </inertial>
        <visual name="Motor-FR_visual">
            <origin xyz="-0.020062 0.001983 0" rpy="1.5708 0 1.5708" />
            <geometry>
                <mesh filename="package://gregor_description/meshes/Motor-FR.stl" scale="0.001 0.001 0.001" />
            </geometry>
            <material name="motor_silver"><color rgba="0.60 0.60 0.62 1.0"/></material>
        </visual>
    </link>
    <link name="laser">
        <inertial>
            <origin xyz="0 0 0.015205" rpy="0 0 0" />
            <mass value="0.075691" />
            <inertia ixx="1.44371e-05" iyy="1.44371e-05" izz="1.57224e-05" ixy="-1.5707e-07" iyz="0" ixz="0" />
        </inertial>
        <visual name="LD06_LiDAR_visual">
            <origin xyz="0 0 0" rpy="1.5708 0 -1.5708" />
            <geometry>
                <mesh filename="package://gregor_description/meshes/LD06_LiDAR.stl" scale="0.001 0.001 0.001" />
            </geometry>
            <material name="lidar_black"><color rgba="0.08 0.08 0.08 1.0"/></material>
        </visual>
    </link>
    <link name="imu_link">
        <inertial>
            <origin xyz="0 0 0.0005" rpy="0 0 0" />
            <mass value="0.000355" />
            <inertia ixx="0" iyy="0" izz="1.184e-08" ixy="0" iyz="0" ixz="0" />
        </inertial>
        <visual name="IMU_visual">
            <origin xyz="-0.008 0 -0.04835" rpy="0 0 1.5708" />
            <geometry>
                <mesh filename="package://gregor_description/meshes/IMU.stl" scale="0.001 0.001 0.001" />
            </geometry>
            <material name="sensor_black"><color rgba="0.08 0.08 0.08 1.0"/></material>
        </visual>
    </link>
    <link name="wheel_fl_link">
        <inertial>
            <origin xyz="-0.000322 -0.026544 0.000171" rpy="0 0 0" />
            <mass value="0.151189" />
            <inertia ixx="7.28318e-05" iyy="9.24437e-05" izz="7.28283e-05" ixy="-1.46474e-07" iyz="3.16777e-07" ixz="0" />
        </inertial>
        <visual name="Mecanum-wheel-FL_visual">
            <origin xyz="-0.03739 -0.100023 -0.035225" rpy="-1.5708 0.785398 -1.5708" />
            <geometry>
                <mesh filename="package://gregor_description/meshes/Mecanum-wheel-FL.stl" scale="0.001 0.001 0.001" />
            </geometry>
            <material name="lidar_black"><color rgba="0.08 0.08 0.08 1.0"/></material>
        </visual>
        <!-- Smooth sphere collision: required for the gz mecanum-drive
             fdir1/mu2 friction trick to produce real sideways motion.
             Visual still uses the mecanum STL above so it looks correct.
             IMPORTANT: this <collision> MUST stay unnamed. The Gazebo
             URDF→SDF parser only merges the <gazebo reference=...><surface>
             friction extension into a wheel collision when the collision
             uses the parser's default lumped name. A custom name attribute
             here makes the merge silently fail and strafing dies. -->
        <collision>
            <origin xyz="0 -0.02654 0" rpy="0 0 0" />
            <geometry>
                <sphere radius="0.0375" />
            </geometry>
        </collision>
    </link>
    <link name="lidar_mount_link">
        <inertial>
            <origin xyz="-0.001079 -3.25633e-05 -2.06706e-05" rpy="0 0 0" />
            <mass value="0.025424" />
            <inertia ixx="6.28089e-06" iyy="3.4596e-06" izz="3.69908e-06" ixy="0" iyz="0" ixz="0" />
        </inertial>
        <visual name="LiDAR-Mount_visual">
            <origin xyz="0 0 0.00615" rpy="0 0 3.14159" />
            <geometry>
                <mesh filename="package://gregor_description/meshes/LiDAR-Mount.stl" scale="0.001 0.001 0.001" />
            </geometry>
            <material name="frame_grey"><color rgba="0.28 0.28 0.28 1.0"/></material>
        </visual>
    </link>
    <link name="wheel_rl_link">
        <inertial>
            <origin xyz="-0.000322 0.026544 -0.000171" rpy="0 0 0" />
            <mass value="0.151189" />
            <inertia ixx="7.28318e-05" iyy="9.24437e-05" izz="7.28283e-05" ixy="1.46474e-07" iyz="3.16777e-07" ixz="0" />
        </inertial>
        <visual name="Mecanum-wheel-RL_visual">
            <origin xyz="-0.03739 0.100023 0.035225" rpy="1.5708 -0.785398 1.5708" />
            <geometry>
                <mesh filename="package://gregor_description/meshes/Mecanum-wheel-RL.stl" scale="0.001 0.001 0.001" />
            </geometry>
            <material name="wheel_black"><color rgba="0.10 0.10 0.10 1.0"/></material>
        </visual>
        <collision>
            <origin xyz="0 0.02654 0" rpy="0 0 0" />
            <geometry>
                <sphere radius="0.0375" />
            </geometry>
        </collision>
    </link>
    <link name="wheel_rr_link">
        <inertial>
            <origin xyz="-0.000322 -0.026544 0.000171" rpy="0 0 0" />
            <mass value="0.151189" />
            <inertia ixx="7.28318e-05" iyy="9.24437e-05" izz="7.28283e-05" ixy="-1.46474e-07" iyz="3.16777e-07" ixz="0" />
        </inertial>
        <visual name="Mecanum-wheel-RR_visual">
            <origin xyz="-0.03739 -0.100023 -0.035225" rpy="-1.5708 0.785398 -1.5708" />
            <geometry>
                <mesh filename="package://gregor_description/meshes/Mecanum-wheel-RR.stl" scale="0.001 0.001 0.001" />
            </geometry>
            <material name="wheel_black"><color rgba="0.10 0.10 0.10 1.0"/></material>
        </visual>
        <collision>
            <origin xyz="0 -0.02654 0" rpy="0 0 0" />
            <geometry>
                <sphere radius="0.0375" />
            </geometry>
        </collision>
    </link>
    <link name="wheel_fr_link">
        <inertial>
            <origin xyz="-0.000322 0.026544 -0.000171" rpy="0 0 0" />
            <mass value="0.151189" />
            <inertia ixx="7.28318e-05" iyy="9.24437e-05" izz="7.28283e-05" ixy="1.46474e-07" iyz="3.16777e-07" ixz="0" />
        </inertial>
        <visual name="Mecanum-wheel-FR_visual">
            <origin xyz="-0.03739 0.100023 0.035225" rpy="1.5708 -0.785398 1.5708" />
            <geometry>
                <!-- NOTE: roller chirality on FR/RL visually looks Type-O (mirror of FL/RR).
                     This is a cosmetic Fusion-export issue and does NOT affect simulated
                     physics, which uses the smooth cylinder collision below + fdir1. -->
                <mesh filename="package://gregor_description/meshes/Mecanum-wheel-FR.stl" scale="0.001 0.001 0.001" />
            </geometry>            <material name="wheel_black"><color rgba="0.10 0.10 0.10 1.0"/></material>            <material name="wheel_black"><color rgba="0.10 0.10 0.10 1.0"/></material>
        </visual>
        <collision>
            <origin xyz="0 0.02654 0" rpy="0 0 0" />
            <geometry>
                <sphere radius="0.0375" />
            </geometry>
        </collision>
    </link>
    <link name="range_right_link">
        <inertial>
            <origin xyz="-0.01275 0.01075 -0.0055" rpy="0 0 0" />
            <mass value="0.011157" />
            <inertia ixx="5.42271e-07" iyy="7.17062e-07" izz="1.03434e-06" ixy="0" iyz="0" ixz="0" />
        </inertial>
        <visual name="Avstands-sensor-hoyre_visual">
            <origin xyz="0.013462 -0.019105 -0.0002" rpy="0 0 0" />
            <geometry>
                <mesh filename="package://gregor_description/meshes/Avstands-sensor-hoyre.stl" scale="0.001 0.001 0.001" />
            </geometry>
            <material name="sensor_white"><color rgba="0.92 0.92 0.92 1.0"/></material>
        </visual>
    </link>
    <link name="motor_rl_link">
        <inertial>
            <origin xyz="0 0.024943 0" rpy="0 0 0" />
            <mass value="0.154411" />
            <inertia ixx="2.67125e-05" iyy="1.20421e-05" izz="2.67125e-05" ixy="0" iyz="0" ixz="0" />
        </inertial>
        <visual name="Motor-RL_visual">
            <origin xyz="-0.020062 0.001983 0" rpy="1.5708 0 1.5708" />
            <geometry>
                <mesh filename="package://gregor_description/meshes/Motor-RL.stl" scale="0.001 0.001 0.001" />
            </geometry>
            <material name="motor_silver"><color rgba="0.60 0.60 0.62 1.0"/></material>
        </visual>
    </link>
    <link name="motor_rr_link">
        <inertial>
            <origin xyz="0 -0.024943 0" rpy="0 0 0" />
            <mass value="0.154411" />
            <inertia ixx="2.67125e-05" iyy="1.20421e-05" izz="2.67125e-05" ixy="0" iyz="0" ixz="0" />
        </inertial>
        <visual name="Motor-RR_visual">
            <origin xyz="-0.020062 -0.001983 0" rpy="-1.5708 0 -1.5708" />
            <geometry>
                <mesh filename="package://gregor_description/meshes/Motor-RR.stl" scale="0.001 0.001 0.001" />
            </geometry>
            <material name="motor_silver"><color rgba="0.60 0.60 0.62 1.0"/></material>
        </visual>
    </link>
    <link name="motor_fl_link">
        <inertial>
            <origin xyz="0 0.024943 0" rpy="0 0 0" />
            <mass value="0.154411" />
            <inertia ixx="2.67125e-05" iyy="1.20421e-05" izz="2.67125e-05" ixy="0" iyz="0" ixz="0" />
        </inertial>
        <visual name="Motor-FL_visual">
            <origin xyz="-0.020062 0.001983 0" rpy="1.5708 0 1.5708" />
            <geometry>
                <mesh filename="package://gregor_description/meshes/Motor-FL.stl" scale="0.001 0.001 0.001" />
            </geometry>
            <material name="motor_silver"><color rgba="0.60 0.60 0.62 1.0"/></material>
        </visual>
    </link>
    <joint name="Chassie_Rigid-1" type="fixed">
        <origin xyz="0.000154 -0.007561 0" rpy="3.14159 0 -1.5708" />
        <parent link="base_link" />
        <child link="battery_link" />
    </joint>
    <joint name="Chassie_Rigid-2" type="fixed">
        <origin xyz="0.000154 -0.007561 0.008" rpy="0 0 -1.5708" />
        <parent link="base_link" />
        <child link="upper_level_link" />
    </joint>
    <joint name="Upper-Level_Revolute-3" type="revolute">
        <!-- Pure Z hinge above upper_level_link.
             rpy yaw = +π/2 cancels upper_level_link's -π/2 yaw,
             so the child frame is aligned with base_link at tilt=0.
             Axis (1,0,0) in this (now base-aligned) frame = base_link X,
             giving front/back tilt of the laser. -->
        <origin xyz="0 0 0.083752" rpy="0 0 1.5708" />
        <parent link="upper_level_link" />
        <child link="lidar_mount_link" />
        <axis xyz="1 0 0" />
        <limit lower="-0.785398" upper="0.785398" effort="10" velocity="5"/>
        <dynamics damping="0.1" friction="0.1"/>
    </joint>
    <joint name="LiDAR-Mount_Rigid-4" type="fixed">
        <!-- Pure Z offset: laser sits ~6 mm above the hinge axis. -->
        <origin xyz="0 0 0.00615" rpy="0 0 3.14159" />
        <parent link="lidar_mount_link" />
        <child link="laser" />
    </joint>
    <joint name="Upper-Level_Rigid-5" type="fixed">
        <origin xyz="0.05725 -0.030492 0.0565" rpy="1.5708 0 0" />
        <parent link="upper_level_link" />
        <child link="camera_link" />
    </joint>
    <joint name="Upper-Level_Rigid-6" type="fixed">
        <origin xyz="0.05725 0.027508 0.0565" rpy="1.5708 0 0" />
        <parent link="upper_level_link" />
        <child link="thermal_camera_link" />
    </joint>
    <joint name="Upper-Level_Rigid-7" type="fixed">
        <origin xyz="0 0 0.04035" rpy="0 0 0" />
        <parent link="upper_level_link" />
        <child link="imu_link" />
    </joint>
    <joint name="Upper-Level_Rigid-8" type="fixed">
        <origin xyz="-0.012 0.085 -0.014802" rpy="0 0 0" />
        <parent link="upper_level_link" />
        <child link="range_left_link" />
    </joint>
    <joint name="Chassie_Rigid-9" type="fixed">
        <origin xyz="0.013001 -0.140622 -0.005" rpy="0 0 -1.5708" />
        <parent link="base_link" />
        <child link="range_front_link" />
    </joint>
    <joint name="Chassie_Rigid-11" type="fixed">
        <origin xyz="-0.012836 0.1255 -0.008" rpy="3.14159 0 -1.5708" />
        <parent link="base_link" />
        <child link="range_rear_link" />
    </joint>
    <joint name="Chassie_Rigid-21" type="fixed">
        <origin xyz="-0.05 0.065 -0.019" rpy="1.5708 -1.5708 0" />
        <parent link="base_link" />
        <child link="motor_rr_link" />
    </joint>
    <joint name="Motor-RR_Revolute-22" type="continuous">
        <origin xyz="0 0 0" rpy="3.14159 0 0" />
        <parent link="motor_rr_link" />
        <child link="wheel_rr_link" />
        <axis xyz="0 1 0" />
        <limit effort="50000" velocity="10"/>
        <dynamics damping="0.001" friction="0.001"/>
    </joint>
    <joint name="Chassie_Rigid-23" type="fixed">
        <origin xyz="-0.05 -0.08 -0.019" rpy="-1.5708 -1.5708 0" />
        <parent link="base_link" />
        <child link="motor_fr_link" />
    </joint>
    <joint name="Chassie_Rigid-24" type="fixed">
        <origin xyz="0.050338 -0.080108 -0.019" rpy="1.5708 -1.5708 0" />
        <parent link="base_link" />
        <child link="motor_fl_link" />
    </joint>
    <joint name="Chassie_Rigid-25" type="fixed">
        <origin xyz="0.050355 0.064715 -0.019" rpy="1.5708 -1.5708 0" />
        <parent link="base_link" />
        <child link="motor_rl_link" />
    </joint>
    <joint name="Motor-RL_Revolute-26" type="continuous">
        <origin xyz="0 0 0" rpy="3.14159 0 0" />
        <parent link="motor_rl_link" />
        <child link="wheel_rl_link" />
        <axis xyz="0 1 0" />
        <limit effort="50000" velocity="10"/>
        <dynamics damping="0.001" friction="0.001"/>
    </joint>
    <joint name="Motor-FR_Revolute-27" type="continuous">
        <origin xyz="0 0 0" rpy="3.14159 0 0" />
        <parent link="motor_fr_link" />
        <child link="wheel_fr_link" />
        <axis xyz="0 -1 0" />
        <limit effort="50000" velocity="10"/>
        <dynamics damping="0.001" friction="0.001"/>
    </joint>
    <joint name="Motor-FL_Revolute-28" type="continuous">
        <origin xyz="0 0 0" rpy="0 0 0" />
        <parent link="motor_fl_link" />
        <child link="wheel_fl_link" />
        <axis xyz="0 -1 0" />
        <limit effort="50000" velocity="10"/>
        <dynamics damping="0.001" friction="0.001"/>
    </joint>
    <joint name="Upper-Level_Rigid-29" type="fixed">
        <origin xyz="0.013496 -0.086222 -0.018" rpy="0 0 0" />
        <parent link="upper_level_link" />
        <child link="range_right_link" />
    </joint>

    <!-- ==================== WHEEL FRICTION ==================== -->
    <!-- Type-X mecanum: each wheel has high friction (mu) along the traction
         diagonal and ~zero friction (mu2) along the free-rolling roller axis.
         The diagonal MUST be expressed in the chassis (base_footprint) frame,
         otherwise the heavy motor->wheel rotations rotate fdir1 out of the
         XY plane and the strafe force vanishes — the symptom being
         "forward fine, strafe just spins".

         Pairing rule (Type-X): the two diagonally-opposite wheels share the
         same fdir1. FL & BR share one diagonal, FR & BL share the other.
         After the +π/2 yaw on base_footprint_to_base_link, the link names
         match physical positions:
             wheel_fl = physical FL  -> fdir1 ( 1, -1, 0)
             wheel_fr = physical FR  -> fdir1 ( 1,  1, 0)
             wheel_rl = physical BL  -> fdir1 ( 1,  1, 0)
             wheel_rr = physical BR  -> fdir1 ( 1, -1, 0) -->
    <gazebo reference="wheel_rl_link">  <!-- physical back-left -->
        <collision>
            <surface>
                <friction>
                    <ode>
                        <mu>5.0</mu>
                        <mu2>0.0</mu2>
                        <fdir1 gz:expressed_in="base_footprint">1 1 0</fdir1>
                    </ode>
                </friction>
                <contact>
                    <ode>
                        <kp>1000000.0</kp>
                        <kd>1.0</kd>
                    </ode>
                </contact>
            </surface>
        </collision>
    </gazebo>
    <gazebo reference="wheel_fl_link">  <!-- physical front-left -->
        <collision>
            <surface>
                <friction>
                    <ode>
                        <mu>5.0</mu>
                        <mu2>0.0</mu2>
                        <fdir1 gz:expressed_in="base_footprint">1 -1 0</fdir1>
                    </ode>
                </friction>
                <contact>
                    <ode>
                        <kp>1000000.0</kp>
                        <kd>1.0</kd>
                    </ode>
                </contact>
            </surface>
        </collision>
    </gazebo>
    <gazebo reference="wheel_rr_link">  <!-- physical back-right -->
        <collision>
            <surface>
                <friction>
                    <ode>
                        <mu>5.0</mu>
                        <mu2>0.0</mu2>
                        <fdir1 gz:expressed_in="base_footprint">1 -1 0</fdir1>
                    </ode>
                </friction>
                <contact>
                    <ode>
                        <kp>1000000.0</kp>
                        <kd>1.0</kd>
                    </ode>
                </contact>
            </surface>
        </collision>
    </gazebo>
    <gazebo reference="wheel_fr_link">  <!-- physical front-right -->
        <collision>
            <surface>
                <friction>
                    <ode>
                        <mu>5.0</mu>
                        <mu2>0.0</mu2>
                        <fdir1 gz:expressed_in="base_footprint">1 1 0</fdir1>
                    </ode>
                </friction>
                <contact>
                    <ode>
                        <kp>1000000.0</kp>
                        <kd>1.0</kd>
                    </ode>
                </contact>
            </surface>
        </collision>
    </gazebo>

    <!-- ==================== IMU SENSOR ==================== -->
    <gazebo reference="imu_link">
        <sensor name="imu_sensor" type="imu">
            <always_on>true</always_on>
            <update_rate>100</update_rate>
            <topic>/imu</topic>
            <!-- Force the published Imu msg's frame_id to a name that
                 actually exists in the TF tree (the URDF link `imu_link`,
                 broadcast by robot_state_publisher via the
                 base_link → upper_level_link → imu_link chain).
                 Without this, gz-sim auto-generates the long scoped name
                 "gregor/imu_link/imu_sensor", which has NO corresponding
                 TF, so MOLA's `imu_gravity_correction` cannot rotate the
                 measured gravity vector into base_link and falls back to
                 assuming an identity sensor pose. The result is that
                 gravity is reported in `imu_link` axes (yawed -90°
                 relative to base_link) — MOLA then re-levels the local
                 map every cycle and the cloud "tilts" with each turn. -->
            <gz_frame_id>imu_link</gz_frame_id>
            <imu>
                <angular_velocity>
                    <x><noise type="gaussian"><mean>0.0</mean><stddev>0.0002</stddev></noise></x>
                    <y><noise type="gaussian"><mean>0.0</mean><stddev>0.0002</stddev></noise></y>
                    <z><noise type="gaussian"><mean>0.0</mean><stddev>0.0002</stddev></noise></z>
                </angular_velocity>
                <linear_acceleration>
                    <x><noise type="gaussian"><mean>0.0</mean><stddev>0.017</stddev></noise></x>
                    <y><noise type="gaussian"><mean>0.0</mean><stddev>0.017</stddev></noise></y>
                    <z><noise type="gaussian"><mean>0.0</mean><stddev>0.017</stddev></noise></z>
                </linear_acceleration>
            </imu>
        </sensor>
    </gazebo>

    <!-- ==================== LIDAR SENSOR ==================== -->
    <!-- Attached to the `laser` link, which is already positioned by the URDF
         kinematic chain (base_link → upper_level_link → [Upper-Level_Revolute-3]
         → lidar_mount_link → laser). Tilt in sim matches the real robot exactly. -->
    <gazebo reference="laser">
        <sensor name="lidar" type="gpu_lidar">
            <always_on>true</always_on>
            <update_rate>10</update_rate>
            <visualize>true</visualize>
            <topic>/scan</topic>
            <gz_frame_id>laser</gz_frame_id>
            <lidar>
                <scan>
                    <horizontal>
                        <samples>450</samples>
                        <resolution>1</resolution>
                        <min_angle>-3.14159</min_angle>
                        <max_angle>3.14159</max_angle>
                    </horizontal>
                    <vertical>
                        <samples>1</samples>
                        <resolution>1</resolution>
                        <min_angle>0.0</min_angle>
                        <max_angle>0.0</max_angle>
                    </vertical>
                </scan>
                <range>
                    <min>0.12</min>
                    <max>12.0</max>
                    <resolution>0.01</resolution>
                </range>
                <!-- Tiny gaussian noise so synthetic walls don't yield
                     perfectly coplanar returns (which collapse GICP
                     normals in MOLA-LO's voxel grid). -->
                <noise type="gaussian">
                    <mean>0.0</mean>
                    <stddev>0.01</stddev>
                </noise>
            </lidar>
        </sensor>
    </gazebo>

    <!-- ==================== GAZEBO PLUGINS ==================== -->
    <gazebo>
        <!-- Mecanum drive: subscribes /cmd_vel, publishes odometry and TF.
             After the +π/2 yaw on base_footprint_to_base_link, the Fusion
             link names finally match physical position, so the wiring is
             the natural mapping. Wheelbase = front↔back X distance in
             base_footprint; wheel_separation = left↔right Y distance.
             Computed from the wheel sphere positions in base_footprint:
               front pair X = +0.080, back pair X = -0.065  →  wheelbase 0.145
               left  pair Y = +0.050, right pair Y = -0.050 →  separation 0.100 -->
        <plugin filename="gz-sim-mecanum-drive-system"
                name="gz::sim::systems::MecanumDrive">
            <front_left_joint>Motor-FL_Revolute-28</front_left_joint>
            <front_right_joint>Motor-FR_Revolute-27</front_right_joint>
            <back_left_joint>Motor-RL_Revolute-26</back_left_joint>
            <back_right_joint>Motor-RR_Revolute-22</back_right_joint>
            <wheelbase>0.145</wheelbase>
            <wheel_separation>0.100</wheel_separation>
            <wheel_radius>0.0375</wheel_radius>
            <topic>/cmd_vel</topic>
            <odom_topic>/wheel/odometry</odom_topic>
            <tf_topic>/model/gregor/tf</tf_topic>
            <frame_id>odom</frame_id>
            <child_frame_id>base_footprint</child_frame_id>
            <odom_publish_frequency>50</odom_publish_frequency>
        </plugin>

        <!-- Publishes all joint states so robot_state_publisher and RViz stay in sync -->
        <plugin filename="gz-sim-joint-state-publisher-system"
                name="gz::sim::systems::JointStatePublisher">
        </plugin>

        <!-- Tilt joint position controller: receives /lidar_cmd_pos -->
        <plugin filename="gz-sim-joint-position-controller-system"
                name="gz::sim::systems::JointPositionController">
            <joint_name>Upper-Level_Revolute-3</joint_name>
            <topic>/lidar_cmd_pos</topic>
            <!-- Tuned for the lidar mount's tiny inertia at a 4 s
                 triangle reference: stiff P, no integrator (the reference
                 already covers the steady-state range), modest D for
                 damping. Old (10/0.1/0.1) lagged badly and oscillated. -->
            <p_gain>80.0</p_gain>
            <i_gain>0.0</i_gain>
            <d_gain>2.0</d_gain>
        </plugin>
    </gazebo>
</robot>